<?xml version="1.0" ?>
<!-- =================================================================================== -->
<!-- |    This document was autogenerated by xacro from /root/ros2_ws/src/jetank_description/urdf/jetank_main.xacro | -->
<!-- |    EDITING THIS FILE BY HAND IS NOT RECOMMENDED                                 | -->
<!-- =================================================================================== -->
<robot name="jetank">
  <!-- ================= PROPERTIES ================== -->
  <!-- ================= INCLUDES ================== -->
  <!-- ================= LINKS ================== -->
  <link name="base_link">
    <visual name="base_link_visual">
      <origin rpy="0.0 0.0 0.0" xyz="0.0 0.0 0.0"/>
      <geometry>
        <mesh filename="file:///root/ros2_ws/install/jetank_description/share/jetank_description/meshes/base_link.stl" scale="0.001 0.001 0.001"/>
      </geometry>
      <material name="base_link_material">
        <color rgba="0.25 0.25 0.25 1"/>
      </material>
    </visual>
    <collision name="base_link_collision">
      <origin rpy="0 0 0" xyz="0 0 0.04"/>
      <geometry>
        <box size="0.2 0.1 0.065"/>
      </geometry>
    </collision>
    <inertial>
      <origin rpy="0.0 0.0 0.0" xyz="-0.0028864851424563968 0.0003605395998919554 0.03729152724217677"/>
      <mass value="0.7639308708503839"/>
      <inertia ixx="0.00150205741988797" ixy="2.0200689378287296e-06" ixz="5.068154904514763e-05" iyy="0.003532242168965159" iyz="4.791503412361428e-06" izz="0.003808278739772123"/>
    </inertial>
  </link>
  <link name="ARM_UPPER">
    <visual name="ARM_UPPER_visual">
      <origin rpy="0.22339825954275927 -1.556184340833111 -0.5813072278980501" xyz="-0.042675603894513275 0.008004289658434232 -0.020301207430691776"/>
      <geometry>
        <mesh filename="file:///root/ros2_ws/install/jetank_description/share/jetank_description/meshes/ARM_UPPER.stl" scale="0.001 0.001 0.001"/>
      </geometry>
      <material name="ARM_UPPER_material">
        <color rgba="0.41 0.45 0.39 1"/>
      </material>
    </visual>
    <collision name="ARM_UPPER_collision">
      <origin rpy="0 0 -0.3926875" xyz="-0.02 0.001 -0.02"/>
      <geometry>
        <box size="0.05 0.005 0.05"/>
      </geometry>
    </collision>
    <inertial>
      <origin rpy="0.0 -4.220565730941431e-35 -6.162975822039156e-33" xyz="-0.022908278643665785 0.0006057553402017391 -0.01928712656788768"/>
      <mass value="0.03565761396104929"/>
      <inertia ixx="1.5443417400841932e-05" ixy="3.625928097526083e-06" ixz="-1.1226347876157484e-06" iyy="2.3764463595438004e-05" iyz="4.6051936175620323e-07" izz="1.3620194048359787e-05"/>
    </inertial>
  </link>
  <link name="ARM_MIDDLE">
    <visual name="ARM_MIDDLE_visual">
      <origin rpy="-3.137540926469612 -0.0010856452132872892 -0.7854003629070162" xyz="-0.0335092778226662 0.03363301371186834 -0.021602684974064732"/>
      <geometry>
        <mesh filename="file:///root/ros2_ws/install/jetank_description/share/jetank_description/meshes/ARM_MIDDLE.stl" scale="0.001 0.001 0.001"/>
      </geometry>
      <material name="ARM_MIDDLE_material">
        <color rgba="0.41 0.45 0.39 1"/>
      </material>
    </visual>
    <collision name="ARM_MIDDLE_collision">
      <origin rpy="0 0 -0.785375" xyz="-0.04 0.04 0"/>
      <geometry>
        <box size="0.115 0.005 0.05"/>
      </geometry>
    </collision>
    <inertial>
      <origin rpy="0.0 2.407412430484311e-35 1.2161079430919492e-49" xyz="-0.03358748266767387 0.03358762804395098 -5.157163600578385e-05"/>
      <mass value="0.06186397464920469"/>
      <inertia ixx="6.497179907917266e-05" ixy="3.117958759744717e-05" ixz="5.2995547323661035e-08" iyy="6.497176903594811e-05" iyz="1.061073116136028e-07" izz="6.838533670855049e-05"/>
    </inertial>
  </link>
  <link name="ARM_LOWER">
    <visual name="ARM_LOWER_visual">
      <origin rpy="-0.00209732879072002 -3.809593605879156e-06 3.137959984463745" xyz="-0.02591983001797696 9.101096039885847e-05 0.0015000976949900147"/>
      <geometry>
        <mesh filename="file:///root/ros2_ws/install/jetank_description/share/jetank_description/meshes/ARM_LOWER.stl" scale="0.001 0.001 0.001"/>
      </geometry>
      <material name="ARM_LOWER_material">
        <color rgba="0.41 0.45 0.39 1"/>
      </material>
    </visual>
    <collision name="ARM_LOWER_collision">
      <origin rpy="0 0 0" xyz="-0.005 0 0.03"/>
      <geometry>
        <cylinder length="0.06" radius="0.02"/>
      </geometry>
    </collision>
    <inertial>
      <origin rpy="4.814824860968091e-35 -0.0 3.2073176521106348e-49" xyz="-0.01064722156754466 -5.485356628246008e-05 0.029442007866704572"/>
      <mass value="0.1036438493797283"/>
      <inertia ixx="8.81458213535141e-05" ixy="4.6845951821403056e-08" ixz="-2.334825910280157e-06" iyy="7.950393953510494e-05" iyz="2.258742793083176e-07" izz="7.219884111762218e-05"/>
    </inertial>
  </link>
  <link name="DRIVER_WHEEL_L">
    <visual name="DRIVER_WHEEL_L_visual">
      <origin rpy="0.5236006817835094 -1.566601673837709 2.617991971944676" xyz="1.452944835456549e-05 -8.388494253024348e-06 -0.003999967103401225"/>
      <geometry>
        <mesh filename="file:///root/ros2_ws/install/jetank_description/share/jetank_description/meshes/DRIVER_WHEEL_L.stl" scale="0.001 0.001 0.001"/>
      </geometry>
      <material name="DRIVER_WHEEL_L_material">
        <color rgba="0.5 0.5 0.4 1"/>
      </material>
    </visual>
    <collision name="DRIVER_WHEEL_L_collision">
      <origin rpy="0 0 0" xyz="0 0 -0.02"/>
      <geometry>
        <cylinder length="0.025" radius="0.025"/>
      </geometry>
    </collision>
    <inertial>
      <origin rpy="0.0 1.8570051196622238e-34 0.0" xyz="6.909868758699923e-05 -5.0523203168468815e-05 -0.019021631303903268"/>
      <mass value="0.10496982138298995"/>
      <inertia ixx="2.2560499003626737e-05" ixy="-5.694123753574936e-11" ixz="-7.452984821786984e-09" iyy="2.251410282101856e-05" iyz="1.5726877697940232e-08" izz="2.4612100281121576e-05"/>
    </inertial>
  </link>
  <link name="DRIVER_WHEEL_R">
    <visual name="DRIVER_WHEEL_R_visual">
      <origin rpy="-0.5236006818924672 -1.5666016738377524 0.52360068175411" xyz="-1.4501981486878535e-05 -8.391092988526694e-06 -0.003999964535501115"/>
      <geometry>
        <mesh filename="file:///root/ros2_ws/install/jetank_description/share/jetank_description/meshes/DRIVER_WHEEL_R.stl" scale="0.001 0.001 0.001"/>
      </geometry>
      <material name="DRIVER_WHEEL_R_material">
        <color rgba="0.5 0.5 0.4 1"/>
      </material>
    </visual>
    <collision name="DRIVER_WHEEL_R_collision">
      <origin rpy="0 0 0" xyz="0 0 -0.02"/>
      <geometry>
        <cylinder length="0.025" radius="0.025"/>
      </geometry>
    </collision>
    <inertial>
      <origin rpy="0.0 -6.360951486702456e-35 0.0" xyz="-6.909654809962084e-05 -2.9269046357853768e-05 -0.019021673226760922"/>
      <mass value="0.1049698213829899"/>
      <inertia ixx="2.2560499004256008e-05" ixy="-2.5324020125478572e-11" ixz="7.453243651668403e-09" iyy="2.251400779881374e-05" iyz="-6.925989762745856e-09" izz="2.4612195302702004e-05"/>
    </inertial>
  </link>
  <link name="FREE_WHEEL_L">
    <visual name="FREE_WHEEL_L_visual">
      <origin rpy="1.5686679065776332 -0.003614548455738382 0.008580194849726693" xyz="5.322111004383068e-05 -3.072566262244614e-05 -0.014649873776578809"/>
      <geometry>
        <mesh filename="file:///root/ros2_ws/install/jetank_description/share/jetank_description/meshes/FREE_WHEEL_L.stl" scale="0.001 0.001 0.001"/>
      </geometry>
      <material name="FREE_WHEEL_L_material">
        <color rgba="0.5 0.5 0.4 1"/>
      </material>
    </visual>
    <collision name="FREE_WHEEL_L_collision">
      <origin rpy="0 0 0" xyz="0 0 -0.02"/>
      <geometry>
        <cylinder length="0.025" radius="0.025"/>
      </geometry>
    </collision>
    <inertial>
      <origin rpy="0.0 1.8570051196622238e-34 0.0" xyz="4.913425615981737e-05 -2.8359849328207787e-05 -0.01352728007660148"/>
      <mass value="0.11488889485414525"/>
      <inertia ixx="4.0681765416765274e-05" ixy="3.7418240329583945e-12" ixz="1.5048848574955645e-09" iyy="4.068201157526234e-05" iyz="-8.518904315297003e-10" izz="4.0263672111597786e-05"/>
    </inertial>
  </link>
  <link name="FREE_WHEEL_R">
    <visual name="FREE_WHEEL_R_visual">
      <origin rpy="1.5686989841660284 0.003632669359659834 -3.8096197296224606e-06" xyz="3.8144482055946226e-05 2.2017392292781324e-05 0.01049990762224918"/>
      <geometry>
        <mesh filename="file:///root/ros2_ws/install/jetank_description/share/jetank_description/meshes/FREE_WHEEL_R.stl" scale="0.001 0.001 0.001"/>
      </geometry>
      <material name="FREE_WHEEL_R_material">
        <color rgba="0.5 0.5 0.4 1"/>
      </material>
    </visual>
    <collision name="FREE_WHEEL_R_collision">
      <origin rpy="0 0 0" xyz="0 0 -0.02"/>
      <geometry>
        <cylinder length="0.025" radius="0.025"/>
      </geometry>
    </collision>
    <inertial>
      <origin rpy="0.0 -6.360951486702456e-35 0.0" xyz="-4.91456850747074e-05 -2.8363712536370045e-05 -0.013527277364732724"/>
      <mass value="0.11488889485415185"/>
      <inertia ixx="4.0681765245256105e-05" ixy="-3.654323655849692e-13" ixz="-1.5325482430441093e-09" iyy="4.0682011546281835e-05" iyz="-8.517839320012789e-10" izz="4.0263672312089414e-05"/>
    </inertial>
  </link>
  <link name="CAMERA">
    <visual name="CAMERA_visual">
      <origin rpy="-3.139495324799226 -3.8095938720097817e-06 0.003632669126105752" xyz="-4.481242470433245e-09 -2.2840283131486673e-09 3.780146231591175e-09"/>
      <geometry>
        <mesh filename="file:///root/ros2_ws/install/jetank_description/share/jetank_description/meshes/CAMERA.stl" scale="0.001 0.001 0.001"/>
      </geometry>
      <material name="CAMERA_material">
        <color rgba="0.84 0.74 0.60 1"/>
      </material>
    </visual>
    <collision name="CAMERA_collision">
      <origin rpy="-3.1415 0 0" xyz="0 0 0"/>
      <geometry>
        <box size="0.01 0.01 0.01"/>
      </geometry>
    </collision>
    <inertial>
      <origin rpy="0.0 -0.0 -1.1739041031382518e-47" xyz="-0.005467113295410968 -4.792118534928669e-06 0.0028147721817248163"/>
      <mass value="0.019177097425958016"/>
      <inertia ixx="1.2125641079973622e-06" ixy="1.5309653202804099e-09" ixz="2.0956885269530622e-07" iyy="1.0782087605613606e-06" iyz="-1.0748684910103616e-10" izz="9.171773161657565e-07"/>
    </inertial>
  </link>
  <link name="CAM_HOLDER">
    <visual name="CAM_HOLDER_visual">
      <origin rpy="2.6179919438508934 -1.5666016740396613 -2.617991943988682" xyz="-0.033848894481244764 1.262198380391766e-07 -0.00012296228401156072"/>
      <geometry>
        <mesh filename="file:///root/ros2_ws/install/jetank_description/share/jetank_description/meshes/CAM_HOLDER.stl" scale="0.001 0.001 0.001"/>
      </geometry>
      <material name="CAM_HOLDER_material">
        <color rgba="0.0 0.5 0.5 1"/>
      </material>
    </visual>
    <collision name="CAM_HOLDER_collision">
      <origin rpy="2.617916666666667 -1.57075 -2.617916666666667" xyz="-0.01 0 0"/>
      <geometry>
        <cylinder length="0.05" radius="0.02"/>
      </geometry>
    </collision>
    <inertial>
      <origin rpy="0.0 -2.0981802744010314e-34 -1.88079096131566e-37" xyz="-0.022309879542198107 1.7398627940234946e-06 -8.10411995800453e-05"/>
      <mass value="0.04320508566431304"/>
      <inertia ixx="2.5816875300630775e-05" ixy="7.560146391039103e-10" ixz="4.858356482648958e-08" iyy="3.164288509735364e-05" iyz="4.0270847025312724e-08" izz="1.2443592739336833e-05"/>
    </inertial>
  </link>
  <link name="BEARING">
    <visual name="BEARING_visual">
      <origin rpy="-3.1394953247999835 -3.809593613640393e-06 0.0036326691260505526" xyz="5.430652114668533e-09 -5.599776194038509e-06 0.0026699942169905724"/>
      <geometry>
        <mesh filename="file:///root/ros2_ws/install/jetank_description/share/jetank_description/meshes/BEARING.stl" scale="0.001 0.001 0.001"/>
      </geometry>
      <material name="BEARING_material">
        <color rgba="0.67 0.74 0.67 1"/>
      </material>
    </visual>
    <collision name="BEARING_collision">
      <origin rpy="-3.1415 0 0" xyz="0 0 0"/>
      <geometry>
        <cylinder length="0.02" radius="0.025"/>
      </geometry>
    </collision>
    <inertial>
      <origin rpy="0.0 -0.0 -8.784755544884209e-38" xyz="-1.4377769774753802e-08 5.306325474567775e-06 -0.0025299943110332545"/>
      <mass value="0.05589211207057759"/>
      <inertia ixx="9.015512369875424e-06" ixy="-6.040612411177808e-14" ixz="2.880142248182665e-11" iyy="9.015545628046614e-06" iyz="-1.585742346699663e-08" izz="1.657627265380158e-05"/>
    </inertial>
  </link>
  <link name="ANTENNA_L">
    <visual name="ANTENNA_L_visual">
      <origin rpy="0.5236006817820806 -1.566601673837696 2.6179919719464855" xyz="0.012558233063349657 -0.006064954690762062 -0.030941931787802295"/>
      <geometry>
        <mesh filename="file:///root/ros2_ws/install/jetank_description/share/jetank_description/meshes/ANTENNA_L.stl" scale="0.001 0.001 0.001"/>
      </geometry>
      <material name="ANTENNA_L_material">
        <color rgba="0.2 0.2 0.2 1"/>
      </material>
    </visual>
    <collision name="ANTENNA_L_collision">
      <origin rpy="1.57075 0 0" xyz="0 0.08 -0.01"/>
      <geometry>
        <cylinder length="0.15" radius="0.01"/>
      </geometry>
    </collision>
    <inertial>
      <origin rpy="0.0 1.8570051196622238e-34 0.0" xyz="0.00010428589158372858 0.05125494812152533 -0.028760898470254075"/>
      <mass value="0.1712590340150529"/>
      <inertia ixx="0.000314068362815308" ixy="-7.600553009246833e-08" ixz="2.77100862291307e-08" iyy="1.1348965126681299e-05" iyz="2.1240148373447467e-05" izz="0.0003064181988690546"/>
    </inertial>
  </link>
  <link name="ANTENNA_R">
    <visual name="ANTENNA_R_visual">
      <origin rpy="-0.523600702813549 -1.5666016737795367 0.5236007026751052" xyz="-0.00011258950982521831 -0.006064999678879916 -0.030987146017140126"/>
      <geometry>
        <mesh filename="file:///root/ros2_ws/install/jetank_description/share/jetank_description/meshes/ANTENNA_R.stl" scale="0.001 0.001 0.001"/>
      </geometry>
      <material name="ANTENNA_R_material">
        <color rgba="0.2 0.2 0.2 1"/>
      </material>
    </visual>
    <collision name="ANTENNA_R_collision">
      <origin rpy="1.57075 0 0" xyz="0 -0.08 -0.01"/>
      <geometry>
        <cylinder length="0.15" radius="0.01"/>
      </geometry>
    </collision>
    <inertial>
      <origin rpy="0.0 -6.360951486702456e-35 0.0" xyz="-0.00010388848222362413 -0.05137513349335263 -0.028545652272082785"/>
      <mass value="0.17125903401505282"/>
      <inertia ixx="0.00031406836395675376" ixy="-7.381378770492805e-08" ixz="-2.723875833525843e-08" iyy="1.117596753400613e-05" iyz="-2.0001701262118792e-05" izz="0.00030659119532028506"/>
    </inertial>
  </link>
  <link name="SERVO_UPPER">
    <visual name="SERVO_UPPER_visual">
      <origin rpy="-3.139353401733166 -0.35794030259148174 0.002848163431076057" xyz="-0.005884888244401978 0.002005539666205546 -0.01282565966177529"/>
      <geometry>
        <mesh filename="file:///root/ros2_ws/install/jetank_description/share/jetank_description/meshes/SERVO_UPPER.stl" scale="0.001 0.001 0.001"/>
      </geometry>
      <material name="SERVO_UPPER_material">
        <color rgba="0.58 0.78 0.78 1"/>
      </material>
    </visual>
    <collision name="SERVO_UPPER_collision">
      <origin rpy="0 -0.3926875 0" xyz="-0.0125 0 -0.0095"/>
      <geometry>
        <box size="0.04 0.04 0.015"/>
      </geometry>
    </collision>
    <inertial>
      <origin rpy="0.0 -0.0 8.152758619563242e-34" xyz="-0.008710205981769175 -0.0008931796940865167 -0.0032610178523219346"/>
      <mass value="0.20982161326472018"/>
      <inertia ixx="3.914539867865734e-05" ixy="-3.681143850732295e-07" ixz="-6.978918972026999e-06" iyy="3.5263719700624594e-05" iyz="-2.158225678133891e-07" izz="5.518967950991577e-05"/>
    </inertial>
  </link>
  <link name="SERVO_LOWER">
    <visual name="SERVO_LOWER_visual">
      <origin rpy="-1.5728936694252873 0.0036326691260359155 3.1415888439710504" xyz="-0.017088390888296067 0.009918027624157234 0.01882732151779485"/>
      <geometry>
        <mesh filename="file:///root/ros2_ws/install/jetank_description/share/jetank_description/meshes/SERVO_LOWER.stl" scale="0.001 0.001 0.001"/>
      </geometry>
      <material name="SERVO_LOWER_material">
        <color rgba="0.58 0.78 0.78 1"/>
      </material>
    </visual>
    <collision name="SERVO_LOWER_collision">
      <origin rpy="-1.57075 0 3.1415" xyz="-0.015 -0.004 0.02"/>
      <geometry>
        <box size="0.04 0.04 0.015"/>
      </geometry>
    </collision>
    <inertial>
      <origin rpy="0.0 -0.0 5.473822126268817e-48" xyz="-0.01778076329454675 -3.6698115345306094e-05 0.01751711641612725"/>
      <mass value="0.20982161326471963"/>
      <inertia ixx="3.6529219753117384e-05" ixy="-1.2716158555447347e-09" ixz="4.283700030945317e-07" iyy="5.780064634567519e-05" iyz="4.7018874707341185e-08" izz="3.5268927790314385e-05"/>
    </inertial>
  </link>
  <link name="GRIPPER_BASE">
    <visual name="GRIPPER_BASE_visual">
      <origin rpy="-0.3748566771788548 -0.0020355939143487573 -1.5671286856792996" xyz="0.017997217528542855 4.248560344255803e-05 -0.005469218003321004"/>
      <geometry>
        <mesh filename="file:///root/ros2_ws/install/jetank_description/share/jetank_description/meshes/GRIPPER_BASE.stl" scale="0.001 0.001 0.001"/>
      </geometry>
      <material name="GRIPPER_BASE_material">
        <color rgba="0.65 0.65 0.62 1"/>
      </material>
    </visual>
    <collision name="GRIPPER_BASE_collision">
      <origin rpy="-0.3926875 0 -1.57075" xyz="0.0175 0 -0.0095"/>
      <geometry>
        <box size="0.04 0.045 0.005"/>
      </geometry>
    </collision>
    <inertial>
      <origin rpy="0.0 -3.469446951953614e-18 -1.6155871338926322e-27" xyz="0.018711205204747332 0.007640083665599069 -0.007388532023619128"/>
      <mass value="0.0366550366587098"/>
      <inertia ixx="1.2285515330750476e-05" ixy="-9.121676749908667e-07" ixz="2.272496699844335e-06" iyy="6.94612066955528e-06" iyz="3.9753185062321765e-07" izz="1.715774480621983e-05"/>
    </inertial>
  </link>
  <link name="GRIPPER_L1">
    <visual name="GRIPPER_L1_visual">
      <origin rpy="-0.0022392674104247065 0.3579393353524086 -3.1387444878467536" xyz="-0.011947302972329262 -2.0470283309416138e-05 -0.010874872369057797"/>
      <geometry>
        <mesh filename="file:///root/ros2_ws/install/jetank_description/share/jetank_description/meshes/GRIPPER_L1.stl" scale="0.001 0.001 0.001"/>
      </geometry>
      <material name="GRIPPER_L1_material">
        <color rgba="0.65 0.65 0.62 1"/>
      </material>
    </visual>
    <collision name="GRIPPER_L1_collision">
      <origin rpy="-0.0022392674104247065 0.3579393353524086 -3.1387444878467536" xyz="-0.011947302972329262 -2.0470283309416138e-05 -0.010874872369057797"/>
      <geometry>
        <mesh filename="file:///root/ros2_ws/install/jetank_description/share/jetank_description/meshes/GRIPPER_L1.stl" scale="0.001 0.001 0.001"/>
      </geometry>
    </collision>
    <inertial>
      <origin rpy="0.0 -0.0 0.0" xyz="-0.012998250088038078 -3.0306803820455697e-05 -0.008065030577021126"/>
      <mass value="0.0062442558314246485"/>
      <inertia ixx="2.2945298088091447e-07" ixy="-2.161025306364326e-09" ixz="-2.2755649847891381e-07" iyy="9.557086105196205e-07" iyz="-4.008141477858269e-10" izz="7.526842531313375e-07"/>
    </inertial>
  </link>
  <link name="GRIPPER_L2">
    <visual name="GRIPPER_L2_visual">
      <origin rpy="0.002239267410431555 0.35793933535233774 -0.0028481657430385345" xyz="0.003188025644908059 -2.9460874184410457e-05 0.008523209934978624"/>
      <geometry>
        <mesh filename="file:///root/ros2_ws/install/jetank_description/share/jetank_description/meshes/GRIPPER_L2.stl" scale="0.001 0.001 0.001"/>
      </geometry>
      <material name="GRIPPER_L2_material">
        <color rgba="0.65 0.65 0.62 1"/>
      </material>
    </visual>
    <collision name="GRIPPER_L2_collision">
      <origin rpy="0.002239267410431555 0.35793933535233774 -0.0028481657430385345" xyz="0.003188025644908059 -2.9460874184410457e-05 0.008523209934978624"/>
      <geometry>
        <mesh filename="file:///root/ros2_ws/install/jetank_description/share/jetank_description/meshes/GRIPPER_L2.stl" scale="0.001 0.001 0.001"/>
      </geometry>
    </collision>
    <inertial>
      <origin rpy="0.0 -0.0 0.0" xyz="-0.0012296239530053298 0.0039691186133053915 0.0036766615181430496"/>
      <mass value="0.02146027585992414"/>
      <inertia ixx="1.2266606930363098e-06" ixy="-9.873904819377294e-07" ixz="1.9653297004488396e-06" iyy="6.125907172840806e-06" iyz="3.6806864768416604e-07" izz="5.756214866640529e-06"/>
    </inertial>
  </link>
  <link name="GRIPPER_R1">
    <visual name="GRIPPER_R1_visual">
      <origin rpy="-0.002239267410441002 0.3579393353523948 -3.1387444878468265" xyz="-0.01194722862140111 -2.0523049998069087e-05 -0.010874850394411446"/>
      <geometry>
        <mesh filename="file:///root/ros2_ws/install/jetank_description/share/jetank_description/meshes/GRIPPER_R1.stl" scale="0.001 0.001 0.001"/>
      </geometry>
      <material name="GRIPPER_R1_material">
        <color rgba="0.65 0.65 0.62 1"/>
      </material>
    </visual>
    <collision name="GRIPPER_R1_collision">
      <origin rpy="-0.002239267410441002 0.3579393353523948 -3.1387444878468265" xyz="-0.01194722862140111 -2.0523049998069087e-05 -0.010874850394411446"/>
      <geometry>
        <mesh filename="file:///root/ros2_ws/install/jetank_description/share/jetank_description/meshes/GRIPPER_R1.stl" scale="0.001 0.001 0.001"/>
      </geometry>
    </collision>
    <inertial>
      <origin rpy="0.0 -0.0 0.0" xyz="-0.012998246756733707 -3.0304779780740975e-05 -0.008065027151216597"/>
      <mass value="0.006244255831424673"/>
      <inertia ixx="2.294529808805892e-07" ixy="-2.1610253063812667e-09" ixz="-2.2755649847891381e-07" iyy="9.557086105191868e-07" iyz="-4.008141478629069e-10" izz="7.526842531311207e-07"/>
    </inertial>
  </link>
  <link name="GRIPPER_R2">
    <visual name="GRIPPER_R2_visual">
      <origin rpy="0.0022392674104621166 -0.3579393353523876 0.002848165742967234" xyz="0.002101980241199648 1.9421618867496714e-05 -0.005619691253464972"/>
      <geometry>
        <mesh filename="file:///root/ros2_ws/install/jetank_description/share/jetank_description/meshes/GRIPPER_R2.stl" scale="0.001 0.001 0.001"/>
      </geometry>
      <material name="GRIPPER_R2_material">
        <color rgba="0.65 0.65 0.62 1"/>
      </material>
    </visual>
    <collision name="GRIPPER_R2_collision">
      <origin rpy="0.0022392674104621166 -0.3579393353523876 0.002848165742967234" xyz="0.002101980241199648 1.9421618867496714e-05 -0.005619691253464972"/>
      <geometry>
        <mesh filename="file:///root/ros2_ws/install/jetank_description/share/jetank_description/meshes/GRIPPER_R2.stl" scale="0.001 0.001 0.001"/>
      </geometry>
    </collision>
    <inertial>
      <origin rpy="0.0 -0.0 -6.018531076210082e-35" xyz="-0.0012584873319152834 0.003975470401698931 -0.0036599972005064174"/>
      <mass value="0.021460275859939086"/>
      <inertia ixx="1.2412063985862897e-06" ixy="-1.0146443397531036e-06" ixz="-1.9668082650145446e-06" iyy="6.1145027700224355e-06" iyz="-3.808193345589322e-07" izz="5.753073563923234e-06"/>
    </inertial>
  </link>
  <!-- ================ JOINTS ================ -->
  <joint name="base_link_rigid_ANTENNA_L_BASE_JOINT" type="fixed">
    <parent link="base_link"/>
    <child link="ANTENNA_L"/>
    <origin rpy="1.57075 0 -3.1415" xyz="0.0718 -0.0442 0.0576"/>
  </joint>
  <joint name="base_link_rigid_ANTENNA_R_BASE_JOINT" type="fixed">
    <parent link="base_link"/>
    <child link="ANTENNA_R"/>
    <origin rpy="-1.57075 0 -3.1415" xyz="0.0718 0.0442 0.0576"/>
  </joint>
  <joint name="base_link_rigid_BEARING_BASE_JOINT" type="fixed">
    <parent link="base_link"/>
    <child link="BEARING"/>
    <origin rpy="3.1415 0 0.0036" xyz="-0.0445 0 0.0767"/>
  </joint>
  <joint name="turn_ARM" type="revolute">
    <parent link="BEARING"/>
    <child link="ARM_LOWER"/>
    <origin rpy="3.1415 0 0" xyz="0 0.0002 -0.0080"/>
    <axis xyz="0 -0.0021 1"/>
    <limit effort="1000000" lower="-1.57075" upper="1.57075" velocity="1000000"/>
  </joint>
  <joint name="FREE_WHEEL_LEFT" type="continuous">
    <parent link="base_link"/>
    <child link="FREE_WHEEL_L"/>
    <origin rpy="1.57075 0 -3.1415" xyz="0.0560 -0.0442 0.0133"/>
    <axis xyz="-0.0036 0.0021 1"/>
  </joint>
  <joint name="FREE_WHEEL_RIGHT" type="continuous">
    <parent link="base_link"/>
    <child link="FREE_WHEEL_R"/>
    <origin rpy="-1.57075 0 -3.1415" xyz="-0.0625 0.0442 0.0133"/>
    <axis xyz="0.0036 0.0021 -1"/>
  </joint>
  <joint name="CAM_HOLDER_rigid_CAMERA_CAMERA_HOLDER" type="fixed">
    <parent link="CAM_HOLDER"/>
    <child link="CAMERA"/>
    <origin rpy="1.57075 0 0" xyz="-0.0338 0 -0.0001"/>
  </joint>
  <joint name="ARM_LOWER_rigid_CAMERA_HOLDER_ARM_LOWER" type="fixed">
    <parent link="ARM_LOWER"/>
    <child link="CAM_HOLDER"/>
    <origin rpy="1.57075 0 0" xyz="-0.0248 0 0.0344"/>
  </joint>
  <joint name="GRIPPER_LEFT_1" type="revolute">
    <parent link="GRIPPER_BASE"/>
    <child link="GRIPPER_L1"/>
    <origin rpy="0 -0.0169 3.1415" xyz="0.0419 0.0051 -0.0149"/>
    <axis xyz="0.3503 0.0032 -0.9366"/>
    <limit effort="1000000" lower="-0.785375" upper="0.0" velocity="1000000"/>
  </joint>
  <joint name="GRIPPER_LEFT_2" type="revolute">
    <parent link="GRIPPER_L1"/>
    <child link="GRIPPER_L2"/>
    <origin rpy="3.1415 0 0" xyz="-0.0281 0 -0.0104"/>
    <axis xyz="-0.3503 0.0032 -0.9366"/>
    <limit effort="1000000" lower="-0.785375" upper="0.0" velocity="1000000"/>
  </joint>
  <joint name="SERVO_UPPER_" type="revolute">
    <parent link="ARM_MIDDLE"/>
    <child link="SERVO_UPPER"/>
    <origin rpy="1.57075 0 0" xyz="-0.0672 0.0672 0"/>
    <axis xyz="-0.0036 1 0.0021"/>
    <limit effort="1000000" lower="-2" upper="1" velocity="1000000"/>
  </joint>
  <joint name="SERVO_LOWER_" type="revolute">
    <parent link="SERVO_LOWER"/>
    <child link="ARM_MIDDLE"/>
    <origin rpy="0 0 0" xyz="-0.0271 0 0.0184"/>
    <axis xyz="-0.0036 -0.0021 1"/>
    <limit effort="1000000" lower="0" upper="0.785375" velocity="1000000"/>
  </joint>
  <joint name="ARM_LOWER_Rigid_SERVO_LOWER_ARM_LOWER" type="fixed">
    <parent link="ARM_LOWER"/>
    <child link="SERVO_LOWER"/>
    <origin rpy="1.57075 0 0" xyz="0.0135 0.0200 0.0672"/>
  </joint>
  <joint name="DRIVING_WHEEL_RIGHT" type="continuous">
    <parent link="base_link"/>
    <child link="DRIVER_WHEEL_R"/>
    <origin rpy="-1.57075 0 -3.1415" xyz="0.0560 0.0442 0.0133"/>
    <axis xyz="0.0036 0.0021 -1"/>
  </joint>
  <joint name="DRIVING_WHEEL_LEFT" type="continuous">
    <parent link="base_link"/>
    <child link="DRIVER_WHEEL_L"/>
    <origin rpy="1.57075 0 3.1415" xyz="-0.0625 -0.0442 0.0133"/>
    <axis xyz="-0.0036 0.0021 1"/>
  </joint>
  <joint name="GRIPPER_RIGHT_2" type="revolute">
    <parent link="GRIPPER_R1"/>
    <child link="GRIPPER_R2"/>
    <origin rpy="0 0 0" xyz="-0.0281 0 -0.0105"/>
    <axis xyz="0.3503 0.0032 -0.9366"/>
    <limit effort="1000000" lower="-0.785375" upper="0" velocity="1000000"/>
  </joint>
  <joint name="GRIPPER_RIGHT_1" type="revolute">
    <parent link="GRIPPER_BASE"/>
    <child link="GRIPPER_R1"/>
    <origin rpy="0 -0.0169 3.1415" xyz="0.0420 -0.0049 -0.0149"/>
    <axis xyz="0.3503 0.0032 -0.9366"/>
    <limit effort="1000000" lower="0" upper="0.785375" velocity="1000000"/>
  </joint>
  <joint name="ARM_UPPER_rigid_GRIPPER_BASE_ARM_UPPER" type="fixed">
    <parent link="ARM_UPPER"/>
    <child link="GRIPPER_BASE"/>
    <origin rpy="-1.57075 0 -3.1415" xyz="-0.0427 0.0080 -0.0203"/>
  </joint>
  <joint name="SERVO_UPPER_rigid_UPPER_ARM_SERVO_UPPER" type="fixed">
    <parent link="SERVO_UPPER"/>
    <child link="ARM_UPPER"/>
    <origin rpy="-1.57075 0 0" xyz="-0.0232 0.0213 -0.0166"/>
  </joint>
  <!-- other of kinds of systems are 'actuator' and 'sensor' but 'system' is more general -->
  <!--
		inside the ros2_control tag we define a plugin inside the <hardware> tag to say
		which plugins to load in Gazebo to simulate a real hardware interface
		further we need to define the joints that are controllable.
		In our case we have:
		- the wheels of the Jetank
		- the base of the arm
		- the 2 servo's
		- the gripper
		- (perhaps the camera holder)
		each joint will have state_interfaces
		and command intefaces. That being either
		position or velocity
	-->
  <ros2_control name="jetank_controller" type="system">
    <hardware>
      <plugin>ign_ros2_control/IgnitionSystem</plugin>
    </hardware>
    <joint name="turn_ARM">
      <command_interface name="position"/>
      <state_interface name="position"/>
      <state_interface name="velocity"/>
    </joint>
    <joint name="DRIVING_WHEEL_LEFT">
      <command_interface name="velocity">
        <param name="min">-10</param>
        <param name="max">10</param>
      </command_interface>
      <state_interface name="position"/>
      <state_interface name="velocity"/>
    </joint>
    <joint name="DRIVING_WHEEL_RIGHT">
      <command_interface name="velocity">
        <param name="min">-10</param>
        <param name="max">10</param>
      </command_interface>
      <state_interface name="position"/>
      <state_interface name="velocity"/>
    </joint>
    <joint name="FREE_WHEEL_LEFT">
      <command_interface name="velocity">
        <param name="min">-10</param>
        <param name="max">10</param>
      </command_interface>
      <state_interface name="position"/>
      <state_interface name="velocity"/>
    </joint>
    <joint name="FREE_WHEEL_RIGHT">
      <command_interface name="velocity">
        <param name="min">-10</param>
        <param name="max">10</param>
      </command_interface>
      <state_interface name="position"/>
      <state_interface name="velocity"/>
    </joint>
    <joint name="SERVO_UPPER_">
      <command_interface name="position"/>
      <state_interface name="position"/>
      <state_interface name="velocity"/>
    </joint>
    <joint name="SERVO_LOWER_">
      <command_interface name="position"/>
      <state_interface name="position"/>
      <state_interface name="velocity"/>
    </joint>
    <joint name="GRIPPER_LEFT_1">
      <command_interface name="position"/>
      <state_interface name="position"/>
      <state_interface name="velocity"/>
    </joint>
    <joint name="GRIPPER_RIGHT_1">
      <command_interface name="position"/>
      <state_interface name="position"/>
      <state_interface name="velocity"/>
    </joint>
    <joint name="GRIPPER_RIGHT_2">
      <command_interface name="position"/>
      <state_interface name="position"/>
      <state_interface name="velocity"/>
    </joint>
    <joint name="GRIPPER_LEFT_2">
      <command_interface name="position"/>
      <state_interface name="position"/>
      <state_interface name="velocity"/>
    </joint>
  </ros2_control>
  <!-- All other sensors such as Camera's, LiDAR's, IMU , etc... -->
  <!--Dummy link -->
  <link name="DUMMY_CAMERA"/>
  <link name="CAMERA_OPTICAL"/>
  <!-- Joint from camera to Dummy link -->
  <joint name="dummy_camera_joint" type="fixed">
    <origin rpy="0 3.1415 0" xyz="0 0 0"/>
    <parent link="CAMERA"/>
    <child link="DUMMY_CAMERA"/>
  </joint>
  <joint name="camera_optical_joint" type="fixed">
    <origin rpy="-1.57075 0 -1.57075" xyz="0 0 0"/>
    <parent link="DUMMY_CAMERA"/>
    <child link="CAMERA_OPTICAL"/>
  </joint>
  <gazebo reference="DUMMY_CAMERA">
    <sensor name="camera" type="camera">
      <always_on>1</always_on>
      <topic>camera</topic>
      <visualize>true</visualize>
      <update_rate>10</update_rate>
      <camera>
        <horizontal_fov>1.089</horizontal_fov>
        <image>
          <!-- (RED) 8 bits + (BLUE) 8 bits  + (GREEN) 8 bits -->
          <format>R8G8B8</format>
          <width>640</width>
          <height>480</height>
        </image>
        <clip>
          <near>0.05</near>
          <far>8.0</far>
        </clip>
      </camera>
    </sensor>
  </gazebo>

  <!--
		required for Gazebo such that ros2_control can work.
		We need to load a config file to tell what controllers to load
	-->
  <gazebo>
    <plugin filename="ign_ros2_control-system" name="ign_ros2_control::IgnitionROS2ControlPlugin">
      <parameters>
				/root/ros2_ws/install/jetank_description/share/jetank_description/config/jetank_controllers.yaml
			</parameters>
    </plugin>
  </gazebo>

</robot>
