<robot xmlns:xacro="http://www.ros.org/wiki/xacro">
    
 <link name="base_link">
        <inertial>
            <origin xyz="-0.0028864851424563968 0.0003605395998919554 0.03729152724217677"
                rpy="0.0 0.0 0.0" />
            <mass value="0.7639308708503839" />
            <inertia ixx="0.00150205741988797" iyy="0.003532242168965159" izz="0.003808278739772123"
                ixy="2.0200689378287296e-06" iyz="4.791503412361428e-06" ixz="5.068154904514763e-05" />
        </inertial>
        <visual name="base_link_visual">
            <origin xyz="0.0 0.0 0.0" rpy="0.0 0.0 0.0" />
            <geometry>
                <mesh filename="file://$(find jetank_bringup)/meshes/base_link.stl"
                    scale="0.001 0.001 0.001" />
            </geometry>
        </visual>
        <collision name="base_link_collision">
            <origin xyz="0.0 0.0 0.0" rpy="0.0 0.0 0.0" />
            <geometry>
                <mesh filename="file://$(find jetank_bringup)/meshes/base_link.stl"
                    scale="0.001 0.001 0.001" />
            </geometry>
        </collision>
    </link>
    <link name="ARM_UPPER">
        <inertial>
            <origin xyz="-0.022908278643665785 0.0006057553402017391 -0.01928712656788768"
                rpy="0.0 -4.220565730941431e-35 -6.162975822039156e-33" />
            <mass value="0.03565761396104929" />
            <inertia ixx="1.5443417400841932e-05" iyy="2.3764463595438004e-05"
                izz="1.3620194048359787e-05" ixy="3.625928097526083e-06"
                iyz="4.6051936175620323e-07" ixz="-1.1226347876157484e-06" />
        </inertial>
        <visual name="ARM_UPPER_visual">
            <origin xyz="-0.042675603894513275 0.008004289658434232 -0.020301207430691776"
                rpy="0.22339825954275927 -1.556184340833111 -0.5813072278980501" />
            <geometry>
                <mesh filename="file://$(find jetank_bringup)/meshes/ARM_UPPER.stl"
                    scale="0.001 0.001 0.001" />
            </geometry>
        </visual>
        <collision name="ARM_UPPER_collision">
            <origin xyz="-0.042675603894513275 0.008004289658434232 -0.020301207430691776"
                rpy="0.22339825954275927 -1.556184340833111 -0.5813072278980501" />
            <geometry>
                <mesh filename="file://$(find jetank_bringup)/meshes/ARM_UPPER.stl"
                    scale="0.001 0.001 0.001" />
            </geometry>
        </collision>
    </link>
    <link name="ARM_MIDDLE">
        <inertial>
            <origin xyz="-0.03358748266767387 0.03358762804395098 -5.157163600578385e-05"
                rpy="0.0 2.407412430484311e-35 1.2161079430919492e-49" />
            <mass value="0.06186397464920469" />
            <inertia ixx="6.497179907917266e-05" iyy="6.497176903594811e-05"
                izz="6.838533670855049e-05" ixy="3.117958759744717e-05" iyz="1.061073116136028e-07"
                ixz="5.2995547323661035e-08" />
        </inertial>
        <visual name="ARM_MIDDLE_visual">
            <origin xyz="-0.0335092778226662 0.03363301371186834 -0.021602684974064732"
                rpy="-3.137540926469612 -0.0010856452132872892 -0.7854003629070162" />
            <geometry>
                <mesh filename="file://$(find jetank_bringup)/meshes/ARM_MIDDLE.stl"
                    scale="0.001 0.001 0.001" />
            </geometry>
        </visual>
        <collision name="ARM_MIDDLE_collision">
            <origin xyz="-0.0335092778226662 0.03363301371186834 -0.021602684974064732"
                rpy="-3.137540926469612 -0.0010856452132872892 -0.7854003629070162" />
            <geometry>
                <mesh filename="file://$(find jetank_bringup)/meshes/ARM_MIDDLE.stl"
                    scale="0.001 0.001 0.001" />
            </geometry>
        </collision>
    </link>
    <link name="ARM_LOWER">
        <inertial>
            <origin xyz="-0.01064722156754466 -5.485356628246008e-05 0.029442007866704572"
                rpy="4.814824860968091e-35 -0.0 3.2073176521106348e-49" />
            <mass value="0.1036438493797283" />
            <inertia ixx="8.81458213535141e-05" iyy="7.950393953510494e-05"
                izz="7.219884111762218e-05" ixy="4.6845951821403056e-08" iyz="2.258742793083176e-07"
                ixz="-2.334825910280157e-06" />
        </inertial>
        <visual name="ARM_LOWER_visual">
            <origin xyz="-0.02591983001797696 9.101096039885847e-05 0.0015000976949900147"
                rpy="-0.00209732879072002 -3.809593605879156e-06 3.137959984463745" />
            <geometry>
                <mesh filename="file://$(find jetank_bringup)/meshes/ARM_LOWER.stl"
                    scale="0.001 0.001 0.001" />
            </geometry>
        </visual>
        <collision name="ARM_LOWER_collision">
            <origin xyz="-0.02591983001797696 9.101096039885847e-05 0.0015000976949900147"
                rpy="-0.00209732879072002 -3.809593605879156e-06 3.137959984463745" />
            <geometry>
                <mesh filename="file://$(find jetank_bringup)/meshes/ARM_LOWER.stl"
                    scale="0.001 0.001 0.001" />
            </geometry>
        </collision>
    </link>
    <link name="DRIVER_WHEEL_L">
        <inertial>
            <origin xyz="6.909868758699923e-05 -5.0523203168468815e-05 -0.019021631303903268"
                rpy="0.0 1.8570051196622238e-34 0.0" />
            <mass value="0.10496982138298995" />
            <inertia ixx="2.2560499003626737e-05" iyy="2.251410282101856e-05"
                izz="2.4612100281121576e-05" ixy="-5.694123753574936e-11"
                iyz="1.5726877697940232e-08" ixz="-7.452984821786984e-09" />
        </inertial>
        <visual name="DRIVER_WHEEL_L_visual">
            <origin xyz="1.452944835456549e-05 -8.388494253024348e-06 -0.003999967103401225"
                rpy="0.5236006817835094 -1.566601673837709 2.617991971944676" />
            <geometry>
                <mesh filename="file://$(find jetank_bringup)/meshes/DRIVER_WHEEL_L.stl"
                    scale="0.001 0.001 0.001" />
            </geometry>
        </visual>
        <collision name="DRIVER_WHEEL_L_collision">
            <origin xyz="1.452944835456549e-05 -8.388494253024348e-06 -0.003999967103401225"
                rpy="0.5236006817835094 -1.566601673837709 2.617991971944676" />
            <geometry>
                <mesh filename="file://$(find jetank_bringup)/meshes/DRIVER_WHEEL_L.stl"
                    scale="0.001 0.001 0.001" />
            </geometry>
        </collision>
    </link>
    <link name="DRIVER_WHEEL_R">
        <inertial>
            <origin xyz="-6.909654809962084e-05 -2.9269046357853768e-05 -0.019021673226760922"
                rpy="0.0 -6.360951486702456e-35 0.0" />
            <mass value="0.1049698213829899" />
            <inertia ixx="2.2560499004256008e-05" iyy="2.251400779881374e-05"
                izz="2.4612195302702004e-05" ixy="-2.5324020125478572e-11"
                iyz="-6.925989762745856e-09" ixz="7.453243651668403e-09" />
        </inertial>
        <visual name="DRIVER_WHEEL_R_visual">
            <origin xyz="-1.4501981486878535e-05 -8.391092988526694e-06 -0.003999964535501115"
                rpy="-0.5236006818924672 -1.5666016738377524 0.52360068175411" />
            <geometry>
                <mesh filename="file://$(find jetank_bringup)/meshes/DRIVER_WHEEL_R.stl"
                    scale="0.001 0.001 0.001" />
            </geometry>
        </visual>
        <collision name="DRIVER_WHEEL_R_collision">
            <origin xyz="-1.4501981486878535e-05 -8.391092988526694e-06 -0.003999964535501115"
                rpy="-0.5236006818924672 -1.5666016738377524 0.52360068175411" />
            <geometry>
                <mesh filename="file://$(find jetank_bringup)/meshes/DRIVER_WHEEL_R.stl"
                    scale="0.001 0.001 0.001" />
            </geometry>
        </collision>
    </link>
    <link name="FREE_WHEEL_L">
        <inertial>
            <origin xyz="4.913425615981737e-05 -2.8359849328207787e-05 -0.01352728007660148"
                rpy="0.0 1.8570051196622238e-34 0.0" />
            <mass value="0.11488889485414525" />
            <inertia ixx="4.0681765416765274e-05" iyy="4.068201157526234e-05"
                izz="4.0263672111597786e-05" ixy="3.7418240329583945e-12"
                iyz="-8.518904315297003e-10" ixz="1.5048848574955645e-09" />
        </inertial>
        <visual name="FREE_WHEEL_L_visual">
            <origin xyz="5.322111004383068e-05 -3.072566262244614e-05 -0.014649873776578809"
                rpy="1.5686679065776332 -0.003614548455738382 0.008580194849726693" />
            <geometry>
                <mesh filename="file://$(find jetank_bringup)/meshes/FREE_WHEEL_L.stl"
                    scale="0.001 0.001 0.001" />
            </geometry>
        </visual>
        <collision name="FREE_WHEEL_L_collision">
            <origin xyz="5.322111004383068e-05 -3.072566262244614e-05 -0.014649873776578809"
                rpy="1.5686679065776332 -0.003614548455738382 0.008580194849726693" />
            <geometry>
                <mesh filename="file://$(find jetank_bringup)/meshes/FREE_WHEEL_L.stl"
                    scale="0.001 0.001 0.001" />
            </geometry>
        </collision>
    </link>
    <link name="FREE_WHEEL_R">
        <inertial>
            <origin xyz="-4.91456850747074e-05 -2.8363712536370045e-05 -0.013527277364732724"
                rpy="0.0 -6.360951486702456e-35 0.0" />
            <mass value="0.11488889485415185" />
            <inertia ixx="4.0681765245256105e-05" iyy="4.0682011546281835e-05"
                izz="4.0263672312089414e-05" ixy="-3.654323655849692e-13"
                iyz="-8.517839320012789e-10" ixz="-1.5325482430441093e-09" />
        </inertial>
        <visual name="FREE_WHEEL_R_visual">
            <origin xyz="3.8144482055946226e-05 2.2017392292781324e-05 0.01049990762224918"
                rpy="1.5686989841660284 0.003632669359659834 -3.8096197296224606e-06" />
            <geometry>
                <mesh filename="file://$(find jetank_bringup)/meshes/FREE_WHEEL_R.stl"
                    scale="0.001 0.001 0.001" />
            </geometry>
        </visual>
        <collision name="FREE_WHEEL_R_collision">
            <origin xyz="3.8144482055946226e-05 2.2017392292781324e-05 0.01049990762224918"
                rpy="1.5686989841660284 0.003632669359659834 -3.8096197296224606e-06" />
            <geometry>
                <mesh filename="file://$(find jetank_bringup)/meshes/FREE_WHEEL_R.stl"
                    scale="0.001 0.001 0.001" />
            </geometry>
        </collision>
    </link>
        <link name="CAMERA">
        <inertial>
            <origin xyz="-0.005467113295410968 -4.792118534928669e-06 0.0028147721817248163"
                rpy="0.0 -0.0 -1.1739041031382518e-47" />
            <mass value="0.019177097425958016" />
            <inertia ixx="1.2125641079973622e-06" iyy="1.0782087605613606e-06"
                izz="9.171773161657565e-07" ixy="1.5309653202804099e-09"
                iyz="-1.0748684910103616e-10" ixz="2.0956885269530622e-07" />
        </inertial>
        <visual name="CAMERA_visual">
            <origin xyz="-4.481242470433245e-09 -2.2840283131486673e-09 3.780146231591175e-09"
                rpy="-3.139495324799226 -3.8095938720097817e-06 0.003632669126105752" />
            <geometry>
                <mesh filename="file://$(find jetank_bringup)/meshes/CAMERA.stl"
                    scale="0.001 0.001 0.001" />
            </geometry>
        </visual>
        <collision name="CAMERA_collision">
            <origin xyz="-4.481242470433245e-09 -2.2840283131486673e-09 3.780146231591175e-09"
                rpy="-3.139495324799226 -3.8095938720097817e-06 0.003632669126105752" />
            <geometry>
                <mesh filename="file://$(find jetank_bringup)/meshes/CAMERA.stl"
                    scale="0.001 0.001 0.001" />
            </geometry>
        </collision>
    </link>
    <link name="CAM_HOLDER">
        <inertial>
            <origin xyz="-0.022309879542198107 1.7398627940234946e-06 -8.10411995800453e-05"
                rpy="0.0 -2.0981802744010314e-34 -1.88079096131566e-37" />
            <mass value="0.04320508566431304" />
            <inertia ixx="2.5816875300630775e-05" iyy="3.164288509735364e-05"
                izz="1.2443592739336833e-05" ixy="7.560146391039103e-10"
                iyz="4.0270847025312724e-08" ixz="4.858356482648958e-08" />
        </inertial>
        <visual name="CAM_HOLDER_visual">
            <origin xyz="-0.033848894481244764 1.262198380391766e-07 -0.00012296228401156072"
                rpy="2.6179919438508934 -1.5666016740396613 -2.617991943988682" />
            <geometry>
                <mesh filename="file://$(find jetank_bringup)/meshes/CAM_HOLDER.stl"
                    scale="0.001 0.001 0.001" />
            </geometry>
        </visual>
        <collision name="CAM_HOLDER_collision">
            <origin xyz="-0.033848894481244764 1.262198380391766e-07 -0.00012296228401156072"
                rpy="2.6179919438508934 -1.5666016740396613 -2.617991943988682" />
            <geometry>
                <mesh filename="file://$(find jetank_bringup)/meshes/CAM_HOLDER.stl"
                    scale="0.001 0.001 0.001" />
            </geometry>
        </collision>
    </link>
    <link name="BEARING">
        <inertial>
            <origin xyz="-1.4377769774753802e-08 5.306325474567775e-06 -0.0025299943110332545"
                rpy="0.0 -0.0 -8.784755544884209e-38" />
            <mass value="0.05589211207057759" />
            <inertia ixx="9.015512369875424e-06" iyy="9.015545628046614e-06"
                izz="1.657627265380158e-05" ixy="-6.040612411177808e-14"
                iyz="-1.585742346699663e-08" ixz="2.880142248182665e-11" />
        </inertial>
        <visual name="BEARING_visual">
            <origin xyz="5.430652114668533e-09 -5.599776194038509e-06 0.0026699942169905724"
                rpy="-3.1394953247999835 -3.809593613640393e-06 0.0036326691260505526" />
            <geometry>
                <mesh filename="file://$(find jetank_bringup)/meshes/BEARING.stl"
                    scale="0.001 0.001 0.001" />
            </geometry>
        </visual>
        <collision name="BEARING_collision">
            <origin xyz="5.430652114668533e-09 -5.599776194038509e-06 0.0026699942169905724"
                rpy="-3.1394953247999835 -3.809593613640393e-06 0.0036326691260505526" />
            <geometry>
                <mesh filename="file://$(find jetank_bringup)/meshes/BEARING.stl"
                    scale="0.001 0.001 0.001" />
            </geometry>
        </collision>
    </link>
    <link name="ANTENNA_L">
        <inertial>
            <origin xyz="0.00010428589158372858 0.05125494812152533 -0.028760898470254075"
                rpy="0.0 1.8570051196622238e-34 0.0" />
            <mass value="0.1712590340150529" />
            <inertia ixx="0.000314068362815308" iyy="1.1348965126681299e-05"
                izz="0.0003064181988690546" ixy="-7.600553009246833e-08"
                iyz="2.1240148373447467e-05" ixz="2.77100862291307e-08" />
        </inertial>
        <visual name="ANTENNA_L_visual">
            <origin xyz="0.012558233063349657 -0.006064954690762062 -0.030941931787802295"
                rpy="0.5236006817820806 -1.566601673837696 2.6179919719464855" />
            <geometry>
                <mesh filename="file://$(find jetank_bringup)/meshes/ANTENNA_L.stl"
                    scale="0.001 0.001 0.001" />
            </geometry>
        </visual>
        <collision name="ANTENNA_L_collision">
            <origin xyz="0.012558233063349657 -0.006064954690762062 -0.030941931787802295"
                rpy="0.5236006817820806 -1.566601673837696 2.6179919719464855" />
            <geometry>
                <mesh filename="file://$(find jetank_bringup)/meshes/ANTENNA_L.stl"
                    scale="0.001 0.001 0.001" />
            </geometry>
        </collision>
    </link>
    <link name="ANTENNA_R">
        <inertial>
            <origin xyz="-0.00010388848222362413 -0.05137513349335263 -0.028545652272082785"
                rpy="0.0 -6.360951486702456e-35 0.0" />
            <mass value="0.17125903401505282" />
            <inertia ixx="0.00031406836395675376" iyy="1.117596753400613e-05"
                izz="0.00030659119532028506" ixy="-7.381378770492805e-08"
                iyz="-2.0001701262118792e-05" ixz="-2.723875833525843e-08" />
        </inertial>
        <visual name="ANTENNA_R_visual">
            <origin xyz="-0.00011258950982521831 -0.006064999678879916 -0.030987146017140126"
                rpy="-0.523600702813549 -1.5666016737795367 0.5236007026751052" />
            <geometry>
                <mesh filename="file://$(find jetank_bringup)/meshes/ANTENNA_R.stl"
                    scale="0.001 0.001 0.001" />
            </geometry>
        </visual>
        <collision name="ANTENNA_R_collision">
            <origin xyz="-0.00011258950982521831 -0.006064999678879916 -0.030987146017140126"
                rpy="-0.523600702813549 -1.5666016737795367 0.5236007026751052" />
            <geometry>
                <mesh filename="file://$(find jetank_bringup)/meshes/ANTENNA_R.stl"
                    scale="0.001 0.001 0.001" />
            </geometry>
        </collision>
    </link>
    <link name="SERVO_UPPER">
        <inertial>
            <origin xyz="-0.008710205981769175 -0.0008931796940865167 -0.0032610178523219346"
                rpy="0.0 -0.0 8.152758619563242e-34" />
            <mass value="0.20982161326472018" />
            <inertia ixx="3.914539867865734e-05" iyy="3.5263719700624594e-05"
                izz="5.518967950991577e-05" ixy="-3.681143850732295e-07"
                iyz="-2.158225678133891e-07" ixz="-6.978918972026999e-06" />
        </inertial>
        <visual name="SERVO_UPPER_visual">
            <origin xyz="-0.005884888244401978 0.002005539666205546 -0.01282565966177529"
                rpy="-3.139353401733166 -0.35794030259148174 0.002848163431076057" />
            <geometry>
                <mesh filename="file://$(find jetank_bringup)/meshes/SERVO_UPPER.stl"
                    scale="0.001 0.001 0.001" />
            </geometry>
        </visual>
        <collision name="SERVO_UPPER_collision">
            <origin xyz="-0.005884888244401978 0.002005539666205546 -0.01282565966177529"
                rpy="-3.139353401733166 -0.35794030259148174 0.002848163431076057" />
            <geometry>
                <mesh filename="file://$(find jetank_bringup)/meshes/SERVO_UPPER.stl"
                    scale="0.001 0.001 0.001" />
            </geometry>
        </collision>
    </link>
    <link name="SERVO_LOWER">
        <inertial>
            <origin xyz="-0.01778076329454675 -3.6698115345306094e-05 0.01751711641612725"
                rpy="0.0 -0.0 5.473822126268817e-48" />
            <mass value="0.20982161326471963" />
            <inertia ixx="3.6529219753117384e-05" iyy="5.780064634567519e-05"
                izz="3.5268927790314385e-05" ixy="-1.2716158555447347e-09"
                iyz="4.7018874707341185e-08" ixz="4.283700030945317e-07" />
        </inertial>
        <visual name="SERVO_LOWER_visual">
            <origin xyz="-0.017088390888296067 0.009918027624157234 0.01882732151779485"
                rpy="-1.5728936694252873 0.0036326691260359155 3.1415888439710504" />
            <geometry>
                <mesh filename="file://$(find jetank_bringup)/meshes/SERVO_LOWER.stl"
                    scale="0.001 0.001 0.001" />
            </geometry>
        </visual>
        <collision name="SERVO_LOWER_collision">
            <origin xyz="-0.017088390888296067 0.009918027624157234 0.01882732151779485"
                rpy="-1.5728936694252873 0.0036326691260359155 3.1415888439710504" />
            <geometry>
                <mesh filename="file://$(find jetank_bringup)/meshes/SERVO_LOWER.stl"
                    scale="0.001 0.001 0.001" />
            </geometry>
        </collision>
    </link>
    <link name="GRIPPER_BASE">
        <inertial>
            <origin xyz="0.018711205204747332 0.007640083665599069 -0.007388532023619128"
                rpy="0.0 -3.469446951953614e-18 -1.6155871338926322e-27" />
            <mass value="0.0366550366587098" />
            <inertia ixx="1.2285515330750476e-05" iyy="6.94612066955528e-06"
                izz="1.715774480621983e-05" ixy="-9.121676749908667e-07"
                iyz="3.9753185062321765e-07" ixz="2.272496699844335e-06" />
        </inertial>
        <visual name="GRIPPER_BASE_visual">
            <origin xyz="0.017997217528542855 4.248560344255803e-05 -0.005469218003321004"
                rpy="-0.3748566771788548 -0.0020355939143487573 -1.5671286856792996" />
            <geometry>
                <mesh filename="file://$(find jetank_bringup)/meshes/GRIPPER_BASE.stl"
                    scale="0.001 0.001 0.001" />
            </geometry>
        </visual>
        <collision name="GRIPPER_BASE_collision">
            <origin xyz="0.017997217528542855 4.248560344255803e-05 -0.005469218003321004"
                rpy="-0.3748566771788548 -0.0020355939143487573 -1.5671286856792996" />
            <geometry>
                <mesh filename="file://$(find jetank_bringup)/meshes/GRIPPER_BASE.stl"
                    scale="0.001 0.001 0.001" />
            </geometry>
        </collision>
    </link>
    <link name="GRIPPER_L1">
        <inertial>
            <origin xyz="-0.012998250088038078 -3.0306803820455697e-05 -0.008065030577021126"
                rpy="0.0 -0.0 0.0" />
            <mass value="0.0062442558314246485" />
            <inertia ixx="2.2945298088091447e-07" iyy="9.557086105196205e-07"
                izz="7.526842531313375e-07" ixy="-2.161025306364326e-09"
                iyz="-4.008141477858269e-10" ixz="-2.2755649847891381e-07" />
        </inertial>
        <visual name="GRIPPER_L1_visual">
            <origin xyz="-0.011947302972329262 -2.0470283309416138e-05 -0.010874872369057797"
                rpy="-0.0022392674104247065 0.3579393353524086 -3.1387444878467536" />
            <geometry>
                <mesh filename="file://$(find jetank_bringup)/meshes/GRIPPER_L1.stl"
                    scale="0.001 0.001 0.001" />
            </geometry>
        </visual>
        <collision name="GRIPPER_L1_collision">
            <origin xyz="-0.011947302972329262 -2.0470283309416138e-05 -0.010874872369057797"
                rpy="-0.0022392674104247065 0.3579393353524086 -3.1387444878467536" />
            <geometry>
                <mesh filename="file://$(find jetank_bringup)/meshes/GRIPPER_L1.stl"
                    scale="0.001 0.001 0.001" />
            </geometry>
        </collision>
    </link>
    <link name="GRIPPER_L2">
        <inertial>
            <origin xyz="-0.0012296239530053298 0.0039691186133053915 0.0036766615181430496"
                rpy="0.0 -0.0 0.0" />
            <mass value="0.02146027585992414" />
            <inertia ixx="1.2266606930363098e-06" iyy="6.125907172840806e-06"
                izz="5.756214866640529e-06" ixy="-9.873904819377294e-07"
                iyz="3.6806864768416604e-07" ixz="1.9653297004488396e-06" />
        </inertial>
        <visual name="GRIPPER_L2_visual">
            <origin xyz="0.003188025644908059 -2.9460874184410457e-05 0.008523209934978624"
                rpy="0.002239267410431555 0.35793933535233774 -0.0028481657430385345" />
            <geometry>
                <mesh filename="file://$(find jetank_bringup)/meshes/GRIPPER_L2.stl"
                    scale="0.001 0.001 0.001" />
            </geometry>
        </visual>
        <collision name="GRIPPER_L2_collision">
            <origin xyz="0.003188025644908059 -2.9460874184410457e-05 0.008523209934978624"
                rpy="0.002239267410431555 0.35793933535233774 -0.0028481657430385345" />
            <geometry>
                <mesh filename="file://$(find jetank_bringup)/meshes/GRIPPER_L2.stl"
                    scale="0.001 0.001 0.001" />
            </geometry>
        </collision>
    </link>
    <link name="GRIPPER_R1">
        <inertial>
            <origin xyz="-0.012998246756733707 -3.0304779780740975e-05 -0.008065027151216597"
                rpy="0.0 -0.0 0.0" />
            <mass value="0.006244255831424673" />
            <inertia ixx="2.294529808805892e-07" iyy="9.557086105191868e-07"
                izz="7.526842531311207e-07" ixy="-2.1610253063812667e-09"
                iyz="-4.008141478629069e-10" ixz="-2.2755649847891381e-07" />
        </inertial>
        <visual name="GRIPPER_R1_visual">
            <origin xyz="-0.01194722862140111 -2.0523049998069087e-05 -0.010874850394411446"
                rpy="-0.002239267410441002 0.3579393353523948 -3.1387444878468265" />
            <geometry>
                <mesh filename="file://$(find jetank_bringup)/meshes/GRIPPER_R1.stl"
                    scale="0.001 0.001 0.001" />
            </geometry>
        </visual>
        <collision name="GRIPPER_R1_collision">
            <origin xyz="-0.01194722862140111 -2.0523049998069087e-05 -0.010874850394411446"
                rpy="-0.002239267410441002 0.3579393353523948 -3.1387444878468265" />
            <geometry>
                <mesh filename="file://$(find jetank_bringup)/meshes/GRIPPER_R1.stl"
                    scale="0.001 0.001 0.001" />
            </geometry>
        </collision>
    </link>
    <link name="GRIPPER_R2">
        <inertial>
            <origin xyz="-0.0012584873319152834 0.003975470401698931 -0.0036599972005064174"
                rpy="0.0 -0.0 -6.018531076210082e-35" />
            <mass value="0.021460275859939086" />
            <inertia ixx="1.2412063985862897e-06" iyy="6.1145027700224355e-06"
                izz="5.753073563923234e-06" ixy="-1.0146443397531036e-06"
                iyz="-3.808193345589322e-07" ixz="-1.9668082650145446e-06" />
        </inertial>
        <visual name="GRIPPER_R2_visual">
            <origin xyz="0.002101980241199648 1.9421618867496714e-05 -0.005619691253464972"
                rpy="0.0022392674104621166 -0.3579393353523876 0.002848165742967234" />
            <geometry>
                <mesh filename="file://$(find jetank_bringup)/meshes/GRIPPER_R2.stl"
                    scale="0.001 0.001 0.001" />
            </geometry>
        </visual>
        <collision name="GRIPPER_R2_collision">
            <origin xyz="0.002101980241199648 1.9421618867496714e-05 -0.005619691253464972"
                rpy="0.0022392674104621166 -0.3579393353523876 0.002848165742967234" />
            <geometry>
                <mesh filename="file://$(find jetank_bringup)/meshes/GRIPPER_R2.stl"
                    scale="0.001 0.001 0.001" />
            </geometry>
        </collision>
    </link>


    <!-- ================ JOINTS ================ -->

    <joint name="base_link_rigid_ANTENNA_L_BASE_JOINT" type="fixed">
        <origin xyz="0.07179583880228464 -0.04420000207379436 0.05764911381971492"
            rpy="1.5728936555844633 -3.8093179705849477e-06 -3.137959984697281" />
        <parent link="base_link" />
        <child link="ANTENNA_L" />
    </joint>
    <joint name="base_link_rigid_BEARING_BASE_JOINT" type="fixed">
        <origin xyz="-0.04452917997058859 -1.5196239222525777e-09 0.07665000059344261"
            rpy="3.1394953248003925 3.8093184609959428e-06 0.0036326691263383853" />
        <parent link="base_link" />
        <child link="BEARING" />
    </joint>
    <joint name="turn ARM" type="revolute">
        <origin xyz="-3.999999486303807e-08 1.68399999926927e-05 -0.008029980000000016"
            rpy="3.1415926535888836 8.470329472757884e-22 2.3620969572063488e-20" />
        <parent link="BEARING" />
        <child link="ARM_LOWER" />
        <axis xyz="-3.999999999999999e-06 -0.002097 0.9999979999999999" />
        <limit lower="-${PI/2}" upper="${PI/2}" effort="1000000" velocity="1000000" />
    </joint>
    <joint name="FREE WHEEL LEFT" type="continuous">
        <origin xyz="0.05602081595239314 -0.04419999897832626 0.0133491162833511"
            rpy="1.5728936555844633 -3.8093179705849477e-06 -3.137959984697281" />
        <parent link="base_link" />
        <child link="FREE_WHEEL_L" />
        <axis xyz="-0.0036329997661754595 0.002096999999255531 0.9999910000008511" />
    </joint>
    <joint name="FREE WHEEL RIGHT" type="continuous">
        <origin xyz="-0.06247918316236259 0.044199998372174795 0.01334911112288851"
            rpy="-1.5686989980047508 -3.8093179709724106e-06 -3.1379599846970962" />
        <parent link="base_link" />
        <child link="FREE_WHEEL_R" />
        <axis xyz="0.003632999766360199 0.002096999999834741 0.9999910000008492" />
    </joint>
    <joint name="CAM_HOLDER_rigid_CAMERA_CAMERA_HOLDER" type="fixed">
        <origin xyz="-0.033848889999999916 1.2999999999152578e-07 -0.00012295999999945018"
            rpy="1.5707963267947316 1.6241874574454326e-14 -2.349358402905514e-19" />
        <parent link="CAM_HOLDER" />
        <child link="CAMERA" />
    </joint>
    <joint name="ARM_LOWER_rigid_CAMERA_HOLDER_ARM_LOWER" type="fixed">
        <origin xyz="-0.02479996000000001 1.7979999999999662e-05 0.03438114"
            rpy="1.5707963267950638 2.5410988417699412e-21 -1.6242292381727147e-14" />
        <parent link="ARM_LOWER" />
        <child link="CAM_HOLDER" />
    </joint>
    <joint name="GRIPPER L1" type="revolute">
        <origin xyz="0.041940669305476776 0.005111130007857552 -0.014907472498325022"
            rpy="-5.535091464327934e-10 -0.016916595705107427 3.141592653589793" />
        <parent link="GRIPPER_BASE" />
        <child link="GRIPPER_L1" />
        <axis xyz="0.350336 0.003237 -0.936618" />
        <limit lower="-${PI/4}" upper="0.0" effort="1000000" velocity="1000000" />
    </joint>
    <joint name="GRIPPER L2" type="revolute">
        <origin xyz="-0.028133550000000014 -8.035999999999932e-05 -0.010416690000000024"
            rpy="3.141592653589793 -4.4510473808249043e-67 -3.2526065174565133e-19" />
        <parent link="GRIPPER_L1" />
        <child link="GRIPPER_L2" />
        <axis xyz="-0.350336 0.0032370000000000003 -0.936618" />
        <limit lower="-${PI/4}" upper="0.0" effort="1000000" velocity="1000000" />
    </joint>
    <joint name="SERVO UPPER" type="revolute">
        <origin xyz="-0.06717496000000145 0.06717525000000088 -0.00010314000001945046"
            rpy="1.5707963267946035 -1.1116756861297127e-16 2.1684043452959522e-19" />
        <parent link="ARM_MIDDLE" />
        <child link="SERVO_UPPER" />
        <axis xyz="-0.0036329999999998286 0.9999909999999781 0.002097000000003716" />
        <limit lower="-${2*PI/PI}" upper="${PI/PI}" effort="1000000" velocity="1000000" />
    </joint>
    <joint name="SERVO LOWER" type="revolute">
        <origin xyz="-0.027086840000000004 -3.859000000304036e-05 0.018351689999999997"
            rpy="4.546362452465827e-13 3.725489130040891e-19 6.153187910945729e-32" />
        <parent link="SERVO_LOWER" />
        <child link="ARM_MIDDLE" />
        <axis xyz="-0.0036329999999999214 -0.002096999999710479 0.9999909999999733" />
        <limit lower="0" upper="${PI/4}" effort="1000000" velocity="1000000" />
    </joint>
    <joint name="ARM_LOWER_Rigid_SERVO_LOWER_ARM_LOWER" type="fixed">
        <origin xyz="0.013493039999999996 0.020010240000000002 0.06719127999999999"
            rpy="1.5707963267947316 1.2705494208814507e-21 -2.114091665950777e-19" />
        <parent link="ARM_LOWER" />
        <child link="SERVO_LOWER" />
    </joint>
    <joint name="DRIVING WHEEL R" type="continuous">
        <origin xyz="0.056020818716250656 0.04419999872667847 0.013349112559074356"
            rpy="-1.5686989980047508 -3.8093179709724106e-06 -3.1379599846970962" />
        <parent link="base_link" />
        <child link="DRIVER_WHEEL_R" />
        <axis xyz="0.003632999766360199 0.002096999999834741 0.9999910000008492" />
    </joint>
    <joint name="DRIVING WHEEL L" type="continuous">
        <origin xyz="-0.06247918592622011 -0.04419999933282993 0.013349114847165264"
            rpy="1.5728936555844633 -3.8093179705849477e-06 -3.137959984697281" />
        <parent link="base_link" />
        <child link="DRIVER_WHEEL_L" />
        <axis xyz="-0.0036329997661754595 0.002096999999255531 0.9999910000008511" />
    </joint>
    <joint name="GRIPPER R2" type="revolute">
        <origin xyz="-0.02809851000000002 -8.002999999999983e-05 -0.010510349999999988"
            rpy="2.168404344970954e-19 5.5511151231257815e-17 -4.336808689941986e-19" />
        <parent link="GRIPPER_R1" />
        <child link="GRIPPER_R2" />
        <axis xyz="0.3503360000000001 0.003237 -0.936618" />
        <limit lower="-${PI/4}" upper="0" effort="1000000" velocity="1000000" />
    </joint>
    <joint name="GRIPPER R1" type="revolute">
        <origin xyz="0.041977348831299825 -0.004888779992154056 -0.014887120054902746"
            rpy="-5.535091464327934e-10 -0.016916595705107427 3.141592653589793" />
        <parent link="GRIPPER_BASE" />
        <child link="GRIPPER_R1" />
        <axis xyz="0.350336 0.003237 -0.936618" />
        <limit lower="0" upper="${PI/4}" effort="1000000" velocity="1000000" />
    </joint>
    <joint name="ARM_UPPER_rigid_GRIPPER_BASE_ARM_UPPER" type="fixed">
        <origin xyz="-0.04267559999999579 0.008004290000004133 -0.02030120999999836"
            rpy="-1.5707963273485313 9.366508094533604e-12 -3.124676057884686" />
        <parent link="ARM_UPPER" />
        <child link="GRIPPER_BASE" />
    </joint>
    <joint name="SERVO_UPPER_rigid_UPPER_ARM_SERVO_UPPER" type="fixed">
        <origin xyz="-0.02320699000000083 0.021300730000000528 -0.016614370000000277"
            rpy="-1.5707963267951013 -5.572799166575498e-17 -1.106970418107717e-16" />
        <parent link="SERVO_UPPER" />
        <child link="ARM_UPPER" />
    </joint>
    <joint name="base_link_rigid_ANTENNA_R_BASE_JOINT" type="fixed">
        <origin xyz="0.07179584156610407 0.044199995652183625 0.05764912009541617"
            rpy="-1.5686989980047508 -3.8093179709724106e-06 -3.1379599846970962" />
        <parent link="base_link" />
        <child link="ANTENNA_R" />
    </joint>
</robot>
